Workbook
Name _DLX1.USE: #REF!
Name _dlx10.use: #REF!
Name cur_scenario: #REF!
Name Data: #REF!
Name DLX1.USE: #REF!
Name FIPSCode: #REF!
Name Focus_Year: #REF!
Name location: #REF!
Name model_columns: #REF!
Name model_data: #REF!
Name model_rows: #REF!
Name scn_columns: #REF!
Name scn_data: #REF!
Name scn_rows: #REF!
Name variable: #REF!
Name vars: #REF!

Sheet tbl_model
B1: Sept 2026
B4: California tourism summary (millions) | Z4: California tourism summary (% change)
T5: Forecast >> | AQ5: Forecast >>
C6: 2009 | D6: =C6+1 -> 2010 | E6: =D6+1 -> 2011 | F6: =E6+1 -> 2012 | G6: =F6+1 -> 2013 | H6: =G6+1 -> 2014 | I6: =H6+1 -> 2015 | J6: =I6+1 -> 2016 | K6: =J6+1 -> 2017 | ... V6: =U6+1 -> 2028 | W6: 2029 | X6: 2030 | AA6: 2010 | AB6: =AA6+1 -> 2011 | AC6: =AB6+1 -> 2012 | AD6: =AC6+1 -> 2013 | AE6: =AD6+1 -> 2014 | AF6: =AE6+1 -> 2015 | AG6: =AF6+1 -> 2016 | AH6: =AG6+1 -> 2017 | AI6: =AH6+1 -> 2018 | ... AT6: =AS6+1 -> 2029 | AU6: 2030
B8: Total visits | C8: 194.93855 | D8: 212.57175 | E8: 222.81795 | F8: 229.73707 | G8: 243.08526 | H8: 251.38253 | I8: 263.88857 | J8: 268.8948 | K8: 273.59261 | L8: 281.47325 | M8: 285.56366 | N8: 140.64816 | O8: 213.43227 | P8: 259.09135 | Q8: 264.11571 | R8: 269.50542 | S8: 271.40346 | T8: 276.33704 | U8: 282.50112 | V8: 289.55266 | W8: 296.48398 | X8: 304.46597 | Z8: Total visits | AA8: =D8/C8-1 -> 0.090455167 | AB8: =E8/D8-1 -> 0.048201138 | AC8: =F8/E8-1 -> 0.031052794 | AD8: =G8/F8-1 -> 0.058102026 | AE8: =H8/G8-1 -> 0.034133143 | AF8: =I8/H8-1 -> 0.049749067 | AG8: =J8/I8-1 -> 0.018970987 | AH8: =K8/J8-1 -> 0.0174708 | ... AU8: =X8/W8-1 -> 0.026922179
B9: Business | C9: 47.646984 | D9: 47.39618 | E9: 48.294479 | F9: 46.216906 | G9: 46.715396 | H9: 46.529859 | I9: 48.014879 | J9: 48.422002 | K9: 49.092414 | L9: 50.925728 | M9: 50.964658 | N9: 16.940475 | O9: 25.84656 | P9: 39.964087 | Q9: 41.575147 | R9: 44.199676 | S9: 44.320417 | T9: 45.419953 | U9: 47.070019 | V9: 47.991488 | W9: 49.399006 | X9: 50.968475 | Z9: Business | AA9: =D9/C9-1 -> -0.0052638039 | AB9: =E9/D9-1 -> 0.018952981 | AC9: =F9/E9-1 -> -0.043018847 | AD9: =G9/F9-1 -> 0.010785865 | AE9: =H9/G9-1 -> -0.0039716413 | AF9: =I9/H9-1 -> 0.03191543 | AG9: =J9/I9-1 -> 0.0084791069 | AH9: =K9/J9-1 -> 0.013845188 | ... AU9: =X9/W9-1 -> 0.031771266
B10: Leisure | C10: 147.29157 | D10: 165.17557 | E10: 174.523 | F10: 183.52017 | G10: 196.36987 | H10: 204.85267 | I10: 215.87369 | J10: 220.4728 | K10: 224.50019 | L10: 230.54753 | M10: 234.599 | N10: 123.70769 | O10: 187.58571 | P10: 219.12726 | Q10: 222.54057 | R10: 225.30574 | S10: 227.08304 | T10: 230.91708 | U10: 235.4311 | V10: 241.56117 | W10: 247.08497 | X10: 253.4975 | Z10: Leisure | AA10: =D10/C10-1 -> 0.12141906 | AB10: =E10/D10-1 -> 0.056590864 | AC10: =F10/E10-1 -> 0.051552894 | AD10: =G10/F10-1 -> 0.070017918 | AE10: =H10/G10-1 -> 0.043198078 | AF10: =I10/H10-1 -> 0.053799767 | AG10: =J10/I10-1 -> 0.021304604 | AH10: =K10/J10-1 -> 0.018267086 | ... AU10: =X10/W10-1 -> 0.025952714
B12: Domestic | Z12: Domestic
B13: Total | C13: 182.782 | D13: 199.276 | E13: 208.615 | F13: 215.056 | G13: 227.17209 | H13: 234.84893 | I13: 246.31063 | J13: 251.08474 | K13: 256.10647 | L13: 263.27741 | M13: 268.10647 | N13: 136.90456 | O13: 208.29111 | P13: 247.33498 | Q13: 249.12128 | R13: 252.98901 | S13: 254.99637 | T13: 259.54198 | U13: 265.20869 | V13: 271.58769 | W13: 277.72022 | X13: 284.91771 | Z13: Total | AA13: =D13/C13-1 -> 0.090238648 | AB13: =E13/D13-1 -> 0.046864649 | AC13: =F13/E13-1 -> 0.03087505 | AD13: =G13/F13-1 -> 0.056339224 | AE13: =H13/G13-1 -> 0.033793072 | AF13: =I13/H13-1 -> 0.048804573 | AG13: =J13/I13-1 -> 0.019382466 | AH13: =K13/J13-1 -> 0.020000147 | ... AU13: =X13/W13-1 -> 0.025916351
B14: Business | C14: 44.243 | D14: 43.823 | E14: 44.234 | F14: 42.576 | G14: 42.92806 | H14: 43.04127 | I14: 44.2532 | J14: 44.68189 | K14: 45.17552 | L14: 47.1046 | M14: 47.35102 | N14: 16.113138 | O14: 25.219339 | P14: 38.247657 | Q14: 39.11204 | R14: 40.731231 | S14: 40.840473 | T14: 41.786476 | U14: 43.366352 | V14: 44.182253 | W14: 45.412442 | X14: 46.827695 | Z14: Business | AA14: =D14/C14-1 -> -0.0094930271 | AB14: =E14/D14-1 -> 0.0093786368 | AC14: =F14/E14-1 -> -0.03748248 | AD14: =G14/F14-1 -> 0.0082689778 | AE14: =H14/G14-1 -> 0.0026372028 | AF14: =I14/H14-1 -> 0.028157394 | AG14: =J14/I14-1 -> 0.0096872091 | AH14: =K14/J14-1 -> 0.011047653 | ... AU14: =X14/W14-1 -> 0.031164436
B15: Group | M15: 9.1669918 | N15: n/a | O15: n/a | P15: n/a | Q15: 6.3322125 | R15: 7.0836924 | S15: 7.2802583 | T15: 7.419098 | U15: 7.6611034 | V15: 7.8130459 | W15: 8.038619 | X15: 8.2974272 | Z15: Group | AM15: n/a | AN15: n/a | AO15: =R15/Q15-1 -> 0.11867572 | AP15: =S15/R15-1 -> 0.027749074 | AQ15: =T15/S15-1 -> 0.019070714 | AR15: =U15/T15-1 -> 0.032619256 | AS15: =V15/U15-1 -> 0.019832977 | AT15: =W15/V15-1 -> 0.028871338 | AU15: =X15/W15-1 -> 0.0321956
B16: Leisure | C16: 138.539 | D16: 155.453 | E16: 164.381 | F16: 172.48 | G16: 184.24403 | H16: 191.80766 | I16: 202.05743 | J16: 206.40285 | K16: 210.93095 | L16: 216.17281 | M16: 220.75545 | N16: 120.79142 | O16: 183.07177 | P16: 209.08732 | Q16: 210.00923 | R16: 212.25778 | S16: 214.15589 | T16: 217.7555 | U16: 221.84234 | V16: 227.40544 | W16: 232.30778 | X16: 238.09002 | Z16: Leisure | AA16: =D16/C16-1 -> 0.12208837 | AB16: =E16/D16-1 -> 0.057432149 | AC16: =F16/E16-1 -> 0.049269675 | AD16: =G16/F16-1 -> 0.068205173 | AE16: =H16/G16-1 -> 0.041052254 | AF16: =I16/H16-1 -> 0.053437761 | AG16: =J16/I16-1 -> 0.021505853 | AH16: =K16/J16-1 -> 0.021938175 | ... AU16: =X16/W16-1 -> 0.024890434
B18: Day | C18: 94.868755 | D18: 104.12634 | E18: 109.562 | F18: 113.258 | G18: 120.11861 | H18: 124.38664 | I18: 131.15424 | J18: 133.27975 | K18: 136.88782 | L18: 141.13786 | M18: 91.089508 | N18: 51.540479 | O18: 71.988052 | P18: 80.939038 | Q18: 82.210021 | R18: 86.028914 | S18: 87.216369 | T18: 88.258791 | U18: 90.09828 | V18: 92.086068 | W18: 94.348953 | X18: 96.982257 | Z18: Day | AA18: =D18/C18-1 -> 0.097583092 | AB18: =E18/D18-1 -> 0.052202542 | AC18: =F18/E18-1 -> 0.033734312 | AD18: =G18/F18-1 -> 0.060575038 | AE18: =H18/G18-1 -> 0.035531822 | AF18: =I18/H18-1 -> 0.054407776 | AG18: =J18/I18-1 -> 0.016206189 | AH18: =K18/J18-1 -> 0.027071418 | ... AU18: =X18/W18-1 -> 0.027910264
B19: Overnight | C19: 87.913246 | D19: 95.14966 | E19: 99.053 | F19: 101.798 | G19: 107.05348 | H19: 110.46229 | I19: 115.15639 | J19: 117.80499 | K19: 119.21865 | L19: 122.13951 | M19: 177.01696 | N19: 85.364076 | O19: 136.30306 | P19: 166.39594 | Q19: 166.91125 | R19: 166.9601 | S19: 167.78 | T19: 171.28319 | U19: 175.11041 | V19: 179.50162 | W19: 183.37127 | X19: 187.93546 | Z19: Overnight | AA19: =D19/C19-1 -> 0.082313126 | AB19: =E19/D19-1 -> 0.041023165 | AC19: =F19/E19-1 -> 0.027712437 | AD19: =G19/F19-1 -> 0.051626559 | AE19: =H19/G19-1 -> 0.031842119 | AF19: =I19/H19-1 -> 0.042495058 | AG19: =J19/I19-1 -> 0.023 | AH19: =K19/J19-1 -> 0.012 | ... AU19: =X19/W19-1 -> 0.024890434
B20: Paid accom. | C20: 61.63983 | D20: 64.9955 | E20: 67.58402 | F20: 69.35036 | G20: 72.35968 | H20: 74.56456 | I20: 77.14878 | J20: 78.833685 | K20: 79.858523 | L20: 82.310122 | M20: 119.46389 | N20: 72.753507 | O20: 97.853745 | P20: 111.10142 | Q20: 111.83054 | R20: 111.19543 | S20: 111.5737 | T20: 114.0746 | U20: 116.79865 | V20: 119.54808 | W20: 122.30863 | X20: 125.35295 | Z20: Paid accom. | AA20: =D20/C20-1 -> 0.054439962 | AB20: =E20/D20-1 -> 0.039826142 | AC20: =F20/E20-1 -> 0.026135468 | AD20: =G20/F20-1 -> 0.043392998 | AE20: =H20/G20-1 -> 0.030471113 | AF20: =I20/H20-1 -> 0.034657483 | AG20: =J20/I20-1 -> 0.021839684 | AH20: =K20/J20-1 -> 0.013 | ... AU20: =X20/W20-1 -> 0.024890434
B21: Unpaid accom. | C21: 26.273416 | D21: 30.15416 | E21: 31.46898 | F21: 32.44764 | G21: 34.6938 | H21: 35.89773 | I21: 38.007612 | J21: 38.971304 | K21: 39.360126 | L21: 39.829384 | M21: 57.553073 | N21: 12.610569 | O21: 38.449315 | P21: 55.294528 | Q21: 55.080714 | R21: 55.764673 | S21: 56.206299 | T21: 57.208584 | U21: 58.311767 | V21: 59.953542 | W21: 61.062631 | X21: 62.582507 | Z21: Unpaid accom. | AA21: =D21/C21-1 -> 0.14770611 | AB21: =E21/D21-1 -> 0.043603279 | AC21: =F21/E21-1 -> 0.031099197 | AD21: =G21/F21-1 -> 0.069224155 | AE21: =H21/G21-1 -> 0.03470158 | AF21: =I21/H21-1 -> 0.058774786 | AG21: =J21/I21-1 -> 0.025355237 | AH21: =K21/J21-1 -> 0.009977135 | ... AU21: =X21/W21-1 -> 0.024890434
B23: Gateway | E23: 96.677282 | F23: 99.253774 | G23: 104.23713 | H23: 106.70171 | I23: 110.43217 | J23: 111.882 | K23: 113.13434 | L23: 115.79551 | M23: 118.64161 | N23: 63.192316 | O23: 87.77371 | P23: 109.05094 | Q23: 111.83453 | R23: 114.35103 | S23: 115.03944 | T23: 117.46189 | U23: 119.83155 | V23: 122.83255 | W23: 125.67012 | X23: 128.92703 | Z23: Gateway | AC23: =F23/E23-1 -> 0.026650437 | AD23: =G23/F23-1 -> 0.050208189 | AE23: =H23/G23-1 -> 0.023644042 | AF23: =I23/H23-1 -> 0.03496153 | AG23: =J23/I23-1 -> 0.013128733 | AH23: =K23/J23-1 -> 0.011193386 | AI23: =L23/K23-1 -> 0.023522161 | AJ23: =M23/L23-1 -> 0.024578683 | ... AU23: =X23/W23-1 -> 0.025916351
B24: Rural/Other | E24: 111.93772 | F24: 115.80223 | G24: 122.93496 | H24: 128.14722 | I24: 135.87846 | J24: 139.20274 | K24: 142.97213 | L24: 147.4819 | M24: 149.46486 | N24: 73.712239 | O24: 120.5174 | P24: 138.28404 | Q24: 137.28675 | R24: 138.63798 | S24: 139.95693 | T24: 142.08009 | U24: 145.37715 | V24: 148.75514 | W24: 152.0501 | X24: 155.99068 | Z24: Rural/Other | AC24: =F24/E24-1 -> 0.034523723 | AD24: =G24/F24-1 -> 0.061594118 | AE24: =H24/G24-1 -> 0.042398481 | AF24: =I24/H24-1 -> 0.060330976 | AG24: =J24/I24-1 -> 0.024465047 | AH24: =K24/J24-1 -> 0.027078443 | AI24: =L24/K24-1 -> 0.03154302 | AJ24: =M24/L24-1 -> 0.013445441 | ... AU24: =X24/W24-1 -> 0.025916351
B26: Fly | C26: 28.463067 | D26: 27.121431 | E26: 23.499252 | F26: 30.820601 | G26: 28.153241 | H26: 29.135773 | I26: 30.251353 | J26: 32.234037 | K26: 33.392967 | L26: 35.543862 | M26: 54.649561 | N26: 17.43321 | O26: 41.770412 | P26: 49.714331 | Q26: 49.572643 | R26: 49.587149 | S26: 50.130543 | T26: 50.692522 | U26: 51.851117 | V26: 53.257574 | W26: 54.514605 | X26: 55.983352 | Z26: Fly | AA26: =D26/C26-1 -> -0.047136029 | AB26: =E26/D26-1 -> -0.13355413 | AC26: =F26/E26-1 -> 0.31155671 | AD26: =G26/F26-1 -> -0.08654471 | AE26: =H26/G26-1 -> 0.034899419 | AF26: =I26/H26-1 -> 0.038289012 | AG26: =J26/I26-1 -> 0.065540321 | AH26: =K26/J26-1 -> 0.035953636 | ... AU26: =X26/W26-1 -> 0.026942267
B27: Drive | C27: 154.31893 | D27: 172.15457 | E27: 185.11575 | F27: 184.2354 | G27: 199.01885 | H27: 205.71316 | I27: 216.05928 | J27: 218.8507 | K27: 222.7135 | L27: 227.73351 | M27: 213.45691 | N27: 119.47135 | O27: 166.5207 | P27: 197.62065 | Q27: 199.54863 | R27: 203.40186 | S27: 204.86582 | T27: 208.84946 | U27: 213.35758 | V27: 218.33012 | W27: 223.20561 | X27: 228.93436 | Z27: Drive | AA27: =D27/C27-1 -> 0.11557646 | AB27: =E27/D27-1 -> 0.075288033 | AC27: =F27/E27-1 -> -0.0047556784 | AD27: =G27/F27-1 -> 0.08024217 | AE27: =H27/G27-1 -> 0.033636568 | AF27: =I27/H27-1 -> 0.050293924 | AG27: =J27/I27-1 -> 0.012919714 | AH27: =K27/J27-1 -> 0.017650393 | ... AU27: =X27/W27-1 -> 0.025665786
B29: International | Z29: International
B30: Total | C30: 12.156553 | D30: 13.295751 | E30: 14.202952 | F30: 14.681073 | G30: 15.913174 | H30: 16.533596 | I30: 17.57794 | J30: 17.810059 | K30: 17.486135 | L30: 18.195846 | M30: 17.457189 | N30: 3.7436084 | O30: 5.1411541 | P30: 11.756367 | Q30: 14.99444 | R30: 16.516406 | S30: 16.407089 | T30: 16.795061 | U30: 17.292424 | V30: 17.964969 | W30: 18.763757 | X30: 19.548257 | Z30: Total | AA30: =D30/C30-1 -> 0.093710679 | AB30: =E30/D30-1 -> 0.06823236 | AC30: =F30/E30-1 -> 0.033663523 | AD30: =G30/F30-1 -> 0.083924457 | AE30: =H30/G30-1 -> 0.038987909 | AF30: =I30/H30-1 -> 0.063164983 | AG30: =J30/I30-1 -> 0.013205148 | AH30: =K30/J30-1 -> -0.018187727 | ... AU30: =X30/W30-1 -> 0.041809323
B31: Overseas | C31: 4.6695526 | D31: 5.5723216 | E31: 6.1449368 | F31: 6.069 | G31: 6.885 | H31: 7.294 | I31: 8.204 | J31: 8.35 | K31: 8.177 | L31: 8.533 | M31: 8.049 | N31: 1.335 | O31: 1.112 | P31: 4.455 | Q31: 6.282 | R31: 6.964 | S31: 6.616 | T31: 6.3678526 | U31: 6.5856762 | V31: 6.9358247 | W31: 7.3967461 | X31: 7.865921 | Z31: Overseas | AA31: =D31/C31-1 -> 0.19333094 | AB31: =E31/D31-1 -> 0.10276062 | AC31: =F31/E31-1 -> -0.012357621 | AD31: =G31/F31-1 -> 0.13445378 | AE31: =H31/G31-1 -> 0.059404503 | AF31: =I31/H31-1 -> 0.12476008 | AG31: =J31/I31-1 -> 0.017796197 | AH31: =K31/J31-1 -> -0.020718563 | ... AU31: =X31/W31-1 -> 0.063429901
B32: Mexico | C32: 6.254 | D32: 6.3674598 | E32: 6.5825151 | F32: 7.0690733 | G32: 7.4608169 | H32: 7.6145503 | I32: 7.7945064 | J32: 7.9182387 | K32: 7.6516776 | L32: 7.940748 | M32: 7.6765304 | N32: 2.0078325 | O32: 3.7189135 | P32: 5.9996565 | Q32: 6.9435304 | R32: 7.8261018 | S32: 8.4112547 | T32: 9.1373261 | U32: 9.3928568 | V32: 9.6637419 | W32: 9.9081521 | X32: 10.137294 | Z32: Mexico | AA32: =D32/C32-1 -> 0.018141957 | AB32: =E32/D32-1 -> 0.033774112 | AC32: =F32/E32-1 -> 0.073916762 | AD32: =G32/F32-1 -> 0.055416542 | AE32: =H32/G32-1 -> 0.020605438 | AF32: =I32/H32-1 -> 0.023633188 | AG32: =J32/I32-1 -> 0.015874296 | AH32: =K32/J32-1 -> -0.033664191 | ... AU32: =X32/W32-1 -> 0.023126614
B33: Canada | C33: 1.233 | D33: 1.35597 | E33: 1.4755 | F33: 1.543 | G33: 1.5673575 | H33: 1.6250455 | I33: 1.5794337 | J33: 1.5418207 | K33: 1.6574573 | L33: 1.7220981 | M33: 1.7316585 | N33: 0.4007759 | O33: 0.31024062 | P33: 1.3017107 | Q33: 1.7689094 | R33: 1.7263045 | S33: 1.3798342 | T33: 1.2898819 | U33: 1.3138914 | V33: 1.3654025 | W33: 1.4588591 | X33: 1.5450422 | Z33: Canada | AA33: =D33/C33-1 -> 0.09973236 | AB33: =E33/D33-1 -> 0.088150918 | AC33: =F33/E33-1 -> 0.045747204 | AD33: =G33/F33-1 -> 0.015785807 | AE33: =H33/G33-1 -> 0.036805898 | AF33: =I33/H33-1 -> -0.028068014 | AG33: =J33/I33-1 -> -0.023814232 | AH33: =K33/J33-1 -> 0.075000031 | ... AU33: =X33/W33-1 -> 0.059075687
B35: Business | C35: 3.4039845 | D35: 3.5731801 | E35: 4.060479 | F35: 3.6409062 | G35: 3.7873355 | H35: 3.4885887 | I35: 3.7616792 | J35: 3.7401125 | K35: 3.9168942 | L35: 3.8211277 | M35: 3.6136381 | N35: 0.82733746 | O35: 0.6272208 | P35: 1.7164296 | Q35: 2.4631072 | R35: 3.4684453 | S35: 3.4799436 | T35: 3.633477 | U35: 3.7036669 | V35: 3.8092345 | W35: 3.9865642 | X35: 4.14078 | Z35: Business | AA35: =D35/C35-1 -> 0.049705168 | AB35: =E35/D35-1 -> 0.13637682 | AC35: =F35/E35-1 -> -0.10333087 | AD35: =G35/F35-1 -> 0.040217825 | AE35: =H35/G35-1 -> -0.078880467 | AF35: =I35/H35-1 -> 0.078281073 | AG35: =J35/I35-1 -> -0.005733266 | AH35: =K35/J35-1 -> 0.047266424 | ... AU35: =X35/W35-1 -> 0.038683895
B36: Leisure | C36: 8.7525681 | D36: 9.7225716 | E36: 10.142 | F36: 11.040167 | G36: 12.125839 | H36: 13.045007 | I36: 13.816261 | J36: 14.069947 | K36: 13.569241 | L36: 14.374718 | M36: 13.843551 | N36: 2.9162709 | O36: 4.5139333 | P36: 10.039938 | Q36: 12.531333 | R36: 13.047961 | S36: 12.927145 | T36: 13.161584 | U36: 13.588758 | V36: 14.155735 | W36: 14.777193 | X36: 15.407477 | Z36: Leisure | AA36: =D36/C36-1 -> 0.11082501 | AB36: =E36/D36-1 -> 0.043139658 | AC36: =F36/E36-1 -> 0.088559172 | AD36: =G36/F36-1 -> 0.098338346 | AE36: =H36/G36-1 -> 0.075802442 | AF36: =I36/H36-1 -> 0.059122531 | AG36: =J36/I36-1 -> 0.018361408 | AH36: =K36/J36-1 -> -0.035586932 | ... AU36: =X36/W36-1 -> 0.042652495
B39: Total travel spending ($ billions) | Z39: Total travel spending ($ billions)
E40: 86.573464 | F40: =SUM(F41,F45) -> 108.91558 | G40: =SUM(G41,G45) -> 111.69229 | H40: =SUM(H41,H45) -> 117.37271 | I40: =SUM(I41,I45) -> 121.93314 | J40: =SUM(J41,J45) -> 126.4022 | K40: =SUM(K41,K45) -> 133.32007 | L40: =SUM(L41,L45) -> 140.34929 | M40: =SUM(M41,M45) -> 144.85065 | N40: =SUM(N41,N45) -> 68.255537 | O40: 105.02807 | P40: 142.50602 | Q40: 151.11481 | R40: 156.18957 | S40: 158.86462 | T40: 166.25502 | U40: 171.73652 | V40: 178.87832 | W40: 187.2233 | X40: 196.29329 | AC40: =F40/E40-1 -> 0.25807123 | AD40: =G40/F40-1 -> 0.025494097 | AE40: =H40/G40-1 -> 0.050857757 | AF40: =I40/H40-1 -> 0.038854316 | AG40: =J40/I40-1 -> 0.036651729 | AH40: =K40/J40-1 -> 0.054728987 | AI40: =L40/K40-1 -> 0.05272438 | AJ40: =M40/L40-1 -> 0.032072588 | ... AU40: =X40/W40-1 -> 0.048444737
B41: Domestic | E41: 86.573464 | F41: 89.64181 | G41: 89.737941 | H41: 94.16416 | I41: 96.377945 | J41: 99.966004 | K41: 106.37466 | L41: 111.7752 | M41: 116.71384 | N41: 62.955578 | O41: 99.854222 | P41: 124.92002 | Q41: 128.56607 | R41: 130.15426 | S41: 133.4499 | T41: 140.24956 | U41: 144.45231 | V41: 150.02783 | W41: 156.39702 | X41: 163.46185 | Z41: Domestic | AC41: =F41/E41-1 -> 0.035442108 | AD41: =G41/F41-1 -> 0.0010723954 | AE41: =H41/G41-1 -> 0.049323825 | AF41: =I41/H41-1 -> 0.02350985 | AG41: =J41/I41-1 -> 0.037229051 | AH41: =K41/J41-1 -> 0.064108329 | AI41: =L41/K41-1 -> 0.050769045 | AJ41: =M41/L41-1 -> 0.044183667 | ... AU41: =X41/W41-1 -> 0.045172435
B42: Business | M42: 28.4754 | N42: 10.245024 | O42: 16.7338 | P42: 26.386274 | Q42: 27.806056 | R42: 28.351607 | S42: 28.706106 | T42: 30.501767 | U42: 31.880928 | V42: 32.946302 | W42: 34.613149 | X42: 36.255019 | Z42: Business | AK42: =N42/M42-1 -> -0.64021491 | AL42: =O42/N42-1 -> 0.6333587 | AM42: =P42/O42-1 -> 0.576825 | AN42: =Q42/P42-1 -> 0.05380763 | AO42: =R42/Q42-1 -> 0.019619857 | AP42: =S42/R42-1 -> 0.012503662 | AQ42: =T42/S42-1 -> 0.062553281 | AR42: =U42/T42-1 -> 0.045215772 | ... AU42: =X42/W42-1 -> 0.047434883
B43: Group | M43: 5.5729759 | N43: n/a | O43: n/a | P43: n/a | Q43: 4.443111 | R43: 4.8713201 | S43: 5.0605907 | T43: 5.3609944 | U43: 5.5642281 | V43: 5.7501637 | W43: 6.053169 | X43: 6.340294 | Z43: Group | AM43: n/a | AN43: n/a | AO43: =R43/Q43-1 -> 0.09637597 | AP43: =S43/R43-1 -> 0.038854069 | AQ43: =T43/S43-1 -> 0.05936137 | AR43: =U43/T43-1 -> 0.037909713 | AS43: =V43/U43-1 -> 0.033416239 | AT43: =W43/V43-1 -> 0.052695076 | AU43: =X43/W43-1 -> 0.047433835
B44: Leisure | M44: 88.238436 | N44: 52.710554 | O44: 83.120422 | P44: 98.533748 | Q44: 100.76002 | R44: 101.80265 | S44: 104.7438 | T44: 109.74779 | U44: 112.57139 | V44: 117.08153 | W44: 121.78387 | X44: 127.20683 | Z44: Leisure | AK44: =N44/M44-1 -> -0.40263499 | AL44: =O44/N44-1 -> 0.57692181 | AM44: =P44/O44-1 -> 0.18543368 | AN44: =Q44/P44-1 -> 0.022593959 | AO44: =R44/Q44-1 -> 0.010347679 | AP44: =S44/R44-1 -> 0.028890686 | AQ44: =T44/S44-1 -> 0.047773651 | AR44: =U44/T44-1 -> 0.025728041 | ... AU44: =X44/W44-1 -> 0.044529407
B45: International | E45: 0 | F45: 19.273774 | G45: 21.954347 | H45: 23.208548 | I45: 25.555199 | J45: 26.4362 | K45: 26.945411 | L45: 28.574089 | M45: 28.136816 | N45: =N136 -> 5.2999588 | O45: 5.1738518 | P45: 17.585997 | Q45: 22.548739 | R45: 26.035312 | S45: 25.414717 | T45: 26.005467 | U45: 27.284209 | V45: 28.850495 | W45: 30.826288 | X45: 32.831438 | Z45: International | AD45: =G45/F45-1 -> 0.13907878 | AE45: =H45/G45-1 -> 0.057127672 | AF45: =I45/H45-1 -> 0.10111149 | AG45: =J45/I45-1 -> 0.034474438 | AH45: =K45/J45-1 -> 0.019261887 | AI45: =L45/K45-1 -> 0.06044362 | AJ45: =M45/L45-1 -> -0.015303138 | AK45: =N45/M45-1 -> -0.81163616 | ... AU45: =X45/W45-1 -> 0.065046742
B46: Business | M46: =M157 -> 6.5425468 | N46: =N157 -> 1.4002254 | O46: 0.77229638 | P46: 2.9103123 | Q46: 4.0809312 | R46: 5.8787734 | S46: 5.7909467 | T46: 6.0336626 | U46: 6.4869087 | V46: 6.7993604 | W46: 7.2776872 | X46: 7.7307786 | Z46: Business | AK46: =N46/M46-1 -> -0.7859816 | AL46: =O46/N46-1 -> -0.44844853 | AM46: =P46/O46-1 -> 2.7683878 | AN46: =Q46/P46-1 -> 0.40223139 | AO46: =R46/Q46-1 -> 0.44054704 | AP46: =S46/R46-1 -> -0.014939639 | AQ46: =T46/S46-1 -> 0.041912994 | AR46: =U46/T46-1 -> 0.075119568 | ... AU46: =X46/W46-1 -> 0.062257614
B47: Leisure | M47: =M158 -> 21.594269 | N47: =N158 -> 3.8997334 | O47: 4.4015554 | P47: 14.675685 | Q47: 18.467808 | R47: 20.156538 | S47: 19.623771 | T47: 19.971804 | U47: 20.797301 | V47: 22.051135 | W47: 23.548601 | X47: 25.100659 | Z47: Leisure | AK47: =N47/M47-1 -> -0.81940887 | AL47: =O47/N47-1 -> 0.12868111 | AM47: =P47/O47-1 -> 2.3342042 | AN47: =Q47/P47-1 -> 0.258395 | AO47: =R47/Q47-1 -> 0.091441834 | AP47: =S47/R47-1 -> -0.026431511 | AQ47: =T47/S47-1 -> 0.017735312 | AR47: =U47/T47-1 -> 0.041333085 | ... AU47: =X47/W47-1 -> 0.065908721
B49: Source: Tourism Economics; STR; Omnitrak (domestic); OAG (air traffic); NTTO (international); Dean Runyan (spending); VisaVue; BTS | Z49: Source: Tourism Economics; STR; Omnitrak (domestic); OAG (air traffic); NTTO (international); Dean Runyan (spending); VisaVue; BTS
B53: Annual domestic leisure trips to California (millions) | Z53: Annual domestic leisure trips to California (% change)
T54: Forecast >> | AQ54: Forecast >>
C55: 2009 | D55: =C55+1 -> 2010 | E55: =D55+1 -> 2011 | F55: =E55+1 -> 2012 | G55: =F55+1 -> 2013 | H55: =G55+1 -> 2014 | I55: =H55+1 -> 2015 | J55: =I55+1 -> 2016 | K55: =J55+1 -> 2017 | ... W55: =V55+1 -> 2029 | X55: 2030 | AA55: 2010 | AB55: =AA55+1 -> 2011 | AC55: =AB55+1 -> 2012 | AD55: =AC55+1 -> 2013 | AE55: =AD55+1 -> 2014 | AF55: =AE55+1 -> 2015 | AG55: =AF55+1 -> 2016 | AH55: =AG55+1 -> 2017 | AI55: =AH55+1 -> 2018 | ... AT55: =AS55+1 -> 2029 | AU55: 2030
...

Sheet compare
D2: Current: Sept 2026 | S2: Previous: May 2026 | AH2: Current - Previous | AP2: % Difference, Current vs Previous
B3: California tourism summary (millions)
C5: 2024 | D5: 2025 | E5: 2026 | F5: 2027 | G5: 2028 | H5: 2029 | I5: 2030 | K5: 2025 | L5: 2026 | M5: 2027 | N5: 2028 | O5: 2029 | P5: 2030 | R5: 2024 | S5: 2025 | T5: 2026 | U5: 2027 | V5: 2028 | W5: 2029 | X5: 2030 | Z5: 2025 | AA5: 2026 | AB5: 2027 | AC5: 2028 | AD5: 2029 | AE5: 2030 | AG5: 2024 | AH5: 2025 | AI5: 2026 | AJ5: 2027 | AK5: 2028 | AL5: 2029 | AM5: 2030 | AO5: 2024 | AP5: 2025 | AQ5: 2026 | AR5: 2027 | AS5: 2028 | AT5: 2029 | AU5: 2030
B7: Total visits | C7: =tbl_model!R8 -> 269.50542 | D7: =tbl_model!S8 -> 271.40346 | E7: =tbl_model!T8 -> 276.33704 | F7: =tbl_model!U8 -> 282.50112 | G7: =tbl_model!V8 -> 289.55266 | H7: =tbl_model!W8 -> 296.48398 | I7: =tbl_model!X8 -> 304.46597 | K7: =D7/C7-1 -> 0.007042667 | L7: =E7/D7-1 -> 0.018178035 | M7: =F7/E7-1 -> 0.02230638 | N7: =G7/F7-1 -> 0.024961113 | O7: =H7/G7-1 -> 0.023938017 | P7: =I7/H7-1 -> 0.026922179 | R7: 269.50542 | S7: 271.40346 | T7: 275.48875 | U7: 282.48908 | V7: 289.156 | W7: 296.00454 | X7: 304.31472 | Z7: =S7/R7-1 -> 0.007042667 | AA7: =T7/S7-1 -> 0.01505249 | AB7: =U7/T7-1 -> 0.025410575 | AC7: =V7/U7-1 -> 0.023600609 | AD7: =W7/V7-1 -> 0.023684608 | AE7: =X7/W7-1 -> 0.028074492 | AG7: =C7-R7 -> 0 | AH7: =D7-S7 -> 0 | AI7: =E7-T7 -> 0.84828373 | AJ7: =F7-U7 -> 0.012035097 | AK7: =G7-V7 -> 0.39666294 | AL7: =H7-W7 -> 0.47943309 | AM7: =I7-X7 -> 0.15125059 | AO7: =C7/R7-1 -> 0 | AP7: =D7/S7-1 -> 0 | AQ7: =E7/T7-1 -> 0.0030791955 | AR7: =F7/U7-1 -> 4.2603759e-05 | AS7: =G7/V7-1 -> 0.0013717957 | AT7: =H7/W7-1 -> 0.0016196815 | AU7: =I7/X7-1 -> 0.00049702028
B8: Business | C8: =tbl_model!R9 -> 44.199676 | D8: =tbl_model!S9 -> 44.320417 | E8: =tbl_model!T9 -> 45.419953 | F8: =tbl_model!U9 -> 47.070019 | G8: =tbl_model!V9 -> 47.991488 | H8: =tbl_model!W9 -> 49.399006 | I8: =tbl_model!X9 -> 50.968475 | K8: =D8/C8-1 -> 0.0027317015 | L8: =E8/D8-1 -> 0.024808799 | M8: =F8/E8-1 -> 0.036329087 | N8: =G8/F8-1 -> 0.019576563 | O8: =H8/G8-1 -> 0.029328494 | P8: =I8/H8-1 -> 0.031771266 | R8: 44.199676 | S8: 44.320417 | T8: 44.742452 | U8: 46.522557 | V8: 47.370258 | W8: 48.74588 | X8: 50.349851 | Z8: =S8/R8-1 -> 0.0027317015 | AA8: =T8/S8-1 -> 0.0095223704 | AB8: =U8/T8-1 -> 0.039785597 | AC8: =V8/U8-1 -> 0.018221292 | AD8: =W8/V8-1 -> 0.029039775 | AE8: =X8/W8-1 -> 0.032904739 | AG8: =C8-R8 -> 0 | AH8: =D8-S8 -> 0 | AI8: =E8-T8 -> 0.6775009 | AJ8: =F8-U8 -> 0.54746116 | AK8: =G8-V8 -> 0.62122922 | AL8: =H8-W8 -> 0.6531256 | AM8: =I8-X8 -> 0.6186241 | AO8: =C8/R8-1 -> 0 | AP8: =D8/S8-1 -> 0 | AQ8: =E8/T8-1 -> 0.015142239 | AR8: =F8/U8-1 -> 0.01176765 | AS8: =G8/V8-1 -> 0.01311433 | AT8: =H8/W8-1 -> 0.013398581 | AU8: =I8/X8-1 -> 0.012286513
B9: Leisure | C9: =tbl_model!R10 -> 225.30574 | D9: =tbl_model!S10 -> 227.08304 | E9: =tbl_model!T10 -> 230.91708 | F9: =tbl_model!U10 -> 235.4311 | G9: =tbl_model!V10 -> 241.56117 | H9: =tbl_model!W10 -> 247.08497 | I9: =tbl_model!X10 -> 253.4975 | K9: =D9/C9-1 -> 0.0078883768 | L9: =E9/D9-1 -> 0.01688389 | M9: =F9/E9-1 -> 0.019548201 | N9: =G9/F9-1 -> 0.026037652 | O9: =H9/G9-1 -> 0.02286708 | P9: =I9/H9-1 -> 0.025952714 | R9: 225.30574 | S9: 227.08304 | T9: 230.7463 | U9: 235.96652 | V9: 241.78574 | W9: 247.25866 | X9: 253.96487 | Z9: =S9/R9-1 -> 0.0078883768 | AA9: =T9/S9-1 -> 0.016131818 | AB9: =U9/T9-1 -> 0.022623212 | AC9: =V9/U9-1 -> 0.024661181 | AD9: =W9/V9-1 -> 0.022635433 | AE9: =X9/W9-1 -> 0.027122231 | AG9: =C9-R9 -> 0 | AH9: =D9-S9 -> 0 | AI9: =E9-T9 -> 0.17078283 | AJ9: =F9-U9 -> -0.53542606 | AK9: =G9-V9 -> -0.22456628 | AL9: =H9-W9 -> -0.17369251 | AM9: =I9-X9 -> -0.46737351 | AO9: =C9/R9-1 -> 0 | AP9: =D9/S9-1 -> 0 | AQ9: =E9/T9-1 -> 0.00074013246 | AR9: =F9/U9-1 -> -0.0022690764 | AS9: =G9/V9-1 -> -0.00092878218 | AT9: =H9/W9-1 -> -0.00070247289 | AU9: =I9/X9-1 -> -0.0018403077
B11: Domestic
B12: Total | C12: =tbl_model!R13 -> 252.98901 | D12: =tbl_model!S13 -> 254.99637 | E12: =tbl_model!T13 -> 259.54198 | F12: =tbl_model!U13 -> 265.20869 | G12: =tbl_model!V13 -> 271.58769 | H12: =tbl_model!W13 -> 277.72022 | I12: =tbl_model!X13 -> 284.91771 | K12: =D12/C12-1 -> 0.0079345515 | L12: =E12/D12-1 -> 0.017826174 | M12: =F12/E12-1 -> 0.021833521 | N12: =G12/F12-1 -> 0.024052747 | O12: =H12/G12-1 -> 0.022580288 | P12: =I12/H12-1 -> 0.025916351 | R12: 252.98901 | S12: 254.99637 | T12: 258.68456 | U12: 265.03272 | V12: 270.96917 | W12: 277.08751 | X12: 284.66332 | Z12: =S12/R12-1 -> 0.0079345515 | AA12: =T12/S12-1 -> 0.014463715 | AB12: =U12/T12-1 -> 0.024540165 | AC12: =V12/U12-1 -> 0.022398935 | AD12: =W12/V12-1 -> 0.022579468 | AE12: =X12/W12-1 -> 0.027340835 | AG12: =C12-R12 -> 0 | AH12: =D12-S12 -> 0 | AI12: =E12-T12 -> 0.85741491 | AJ12: =F12-U12 -> 0.17596831 | AK12: =G12-V12 -> 0.6185152 | AL12: =H12-W12 -> 0.63270369 | AM12: =I12-X12 -> 0.25439429 | AO12: =C12/R12-1 -> 0 | AP12: =D12/S12-1 -> 0 | AQ12: =E12/T12-1 -> 0.003314519 | AR12: =F12/U12-1 -> 0.00066394936 | AS12: =G12/V12-1 -> 0.0022826035 | AT12: =H12/W12-1 -> 0.0022834074 | AU12: =I12/X12-1 -> 0.00089366725
B13: Business | C13: =tbl_model!R14 -> 40.731231 | D13: =tbl_model!S14 -> 40.840473 | E13: =tbl_model!T14 -> 41.786476 | F13: =tbl_model!U14 -> 43.366352 | G13: =tbl_model!V14 -> 44.182253 | H13: =tbl_model!W14 -> 45.412442 | I13: =tbl_model!X14 -> 46.827695 | K13: =D13/C13-1 -> 0.002682023 | L13: =E13/D13-1 -> 0.023163367 | M13: =F13/E13-1 -> 0.037808297 | N13: =G13/F13-1 -> 0.018814163 | O13: =H13/G13-1 -> 0.027843495 | P13: =I13/H13-1 -> 0.031164436 | R13: 40.731231 | S13: 40.840473 | T13: 41.213925 | U13: 42.893744 | V13: 43.627403 | W13: 44.844962 | X13: 46.309653 | Z13: =S13/R13-1 -> 0.002682023 | AA13: =T13/S13-1 -> 0.0091441541 | AB13: =U13/T13-1 -> 0.040758523 | AC13: =V13/U13-1 -> 0.017104114 | AD13: =W13/V13-1 -> 0.027908115 | AE13: =X13/W13-1 -> 0.032661215 | AG13: =C13-R13 -> 0 | AH13: =D13-S13 -> 0 | AI13: =E13-T13 -> 0.57255129 | AJ13: =F13-U13 -> 0.47260808 | AK13: =G13-V13 -> 0.5548502 | AL13: =H13-W13 -> 0.56747995 | AM13: =I13-X13 -> 0.51804211 | AO13: =C13/R13-1 -> 0 | AP13: =D13/S13-1 -> 0 | AQ13: =E13/T13-1 -> 0.013892181 | AR13: =F13/U13-1 -> 0.011018112 | AS13: =G13/V13-1 -> 0.012717929 | AT13: =H13/W13-1 -> 0.012654263 | AU13: =I13/X13-1 -> 0.011186482
B14: Group | C14: =tbl_model!R15 -> 7.0836924 | D14: =tbl_model!S15 -> 7.2802583 | E14: =tbl_model!T15 -> 7.419098 | F14: =tbl_model!U15 -> 7.6611034 | G14: =tbl_model!V15 -> 7.8130459 | H14: =tbl_model!W15 -> 8.038619 | I14: =tbl_model!X15 -> 8.2974272 | K14: =D14/C14-1 -> 0.027749074 | L14: =E14/D14-1 -> 0.019070714 | M14: =F14/E14-1 -> 0.032619256 | N14: =G14/F14-1 -> 0.019832977 | O14: =H14/G14-1 -> 0.028871338 | P14: =I14/H14-1 -> 0.0321956 | R14: 7.0836924 | S14: 7.2802583 | T14: 7.4202984 | U14: 7.6841251 | V14: 7.8233708 | W14: 8.049748 | X14: 8.3209752 | Z14: =S14/R14-1 -> 0.027749074 | AA14: =T14/S14-1 -> 0.019235596 | AB14: =U14/T14-1 -> 0.035554731 | AC14: =V14/U14-1 -> 0.018121219 | AD14: =W14/V14-1 -> 0.028936023 | AE14: =X14/W14-1 -> 0.033693877 | AG14: =C14-R14 -> 0 | AH14: =D14-S14 -> 0 | AI14: =E14-T14 -> -0.0012003845 | AJ14: =F14-U14 -> -0.02302164 | AK14: =G14-V14 -> -0.010324858 | AL14: =H14-W14 -> -0.011129006 | AM14: =I14-X14 -> -0.02354806 | AO14: =C14/R14-1 -> 0 | AP14: =D14/S14-1 -> 0 | AQ14: =E14/T14-1 -> -0.00016177038 | AR14: =F14/U14-1 -> -0.0029960001 | AS14: =G14/V14-1 -> -0.0013197455 | AT14: =H14/W14-1 -> -0.0013825284 | AU14: =I14/X14-1 -> -0.0028299639
B15: Leisure | C15: =tbl_model!R16 -> 212.25778 | D15: =tbl_model!S16 -> 214.15589 | E15: =tbl_model!T16 -> 217.7555 | F15: =tbl_model!U16 -> 221.84234 | G15: =tbl_model!V16 -> 227.40544 | H15: =tbl_model!W16 -> 232.30778 | I15: =tbl_model!X16 -> 238.09002 | K15: =D15/C15-1 -> 0.0089424861 | L15: =E15/D15-1 -> 0.016808348 | M15: =F15/E15-1 -> 0.01876802 | N15: =G15/F15-1 -> 0.0250768 | O15: =H15/G15-1 -> 0.021557708 | P15: =I15/H15-1 -> 0.024890434 | R15: 212.25778 | S15: 214.15589 | T15: 217.47064 | U15: 222.13898 | V15: 227.34177 | W15: 232.24255 | X15: 238.35367 | Z15: =S15/R15-1 -> 0.0089424861 | AA15: =T15/S15-1 -> 0.015478179 | AB15: =U15/T15-1 -> 0.021466544 | AC15: =V15/U15-1 -> 0.023421333 | AD15: =W15/V15-1 -> 0.021556889 | AE15: =X15/W15-1 -> 0.026313494 | AG15: =C15-R15 -> 0 | AH15: =D15-S15 -> 0 | AI15: =E15-T15 -> 0.28486362 | AJ15: =F15-U15 -> -0.29663978 | AK15: =G15-V15 -> 0.063664992 | AL15: =H15-W15 -> 0.065223737 | AM15: =I15-X15 -> -0.26364783 | AO15: =C15/R15-1 -> 0 | AP15: =D15/S15-1 -> 0 | AQ15: =E15/T15-1 -> 0.0013098946 | AR15: =F15/U15-1 -> -0.0013353792 | AS15: =G15/V15-1 -> 0.00028004089 | AT15: =H15/W15-1 -> 0.00028084318 | AU15: =I15/X15-1 -> -0.0011061203
B17: Day | C17: =tbl_model!R18 -> 86.028914 | D17: =tbl_model!S18 -> 87.216369 | E17: =tbl_model!T18 -> 88.258791 | F17: =tbl_model!U18 -> 90.09828 | G17: =tbl_model!V18 -> 92.086068 | H17: =tbl_model!W18 -> 94.348953 | I17: =tbl_model!X18 -> 96.982257 | K17: =D17/C17-1 -> 0.01380298 | L17: =E17/D17-1 -> 0.011952132 | M17: =F17/E17-1 -> 0.020841989 | N17: =G17/F17-1 -> 0.02206245 | O17: =H17/G17-1 -> 0.024573585 | P17: =I17/H17-1 -> 0.027910264 | R17: 86.028914 | S17: 87.216369 | T17: 88.137429 | U17: 90.212969 | V17: 92.054908 | W17: 94.316413 | X17: 97.082871 | Z17: =S17/R17-1 -> 0.01380298 | AA17: =T17/S17-1 -> 0.010560624 | AB17: =U17/T17-1 -> 0.023548915 | AC17: =V17/U17-1 -> 0.020417673 | AD17: =W17/V17-1 -> 0.024566913 | AE17: =X17/W17-1 -> 0.029331668 | AG17: =C17-R17 -> 0 | AH17: =D17-S17 -> 0 | AI17: =E17-T17 -> 0.12136231 | AJ17: =F17-U17 -> -0.11468981 | AK17: =G17-V17 -> 0.031160132 | AL17: =H17-W17 -> 0.032540002 | AM17: =I17-X17 -> -0.10061355 | AO17: =C17/R17-1 -> 0 | AP17: =D17/S17-1 -> 0 | AQ17: =E17/T17-1 -> 0.0013769668 | AR17: =F17/U17-1 -> -0.0012713228 | AS17: =G17/V17-1 -> 0.00033849506 | AT17: =H17/W17-1 -> 0.0003450089 | AU17: =I17/X17-1 -> -0.0010363677
B18: Overnight | C18: =tbl_model!R19 -> 166.9601 | D18: =tbl_model!S19 -> 167.78 | E18: =tbl_model!T19 -> 171.28319 | F18: =tbl_model!U19 -> 175.11041 | G18: =tbl_model!V19 -> 179.50162 | H18: =tbl_model!W19 -> 183.37127 | I18: =tbl_model!X19 -> 187.93546 | K18: =D18/C18-1 -> 0.0049107479 | L18: =E18/D18-1 -> 0.020879653 | M18: =F18/E18-1 -> 0.022344438 | N18: =G18/F18-1 -> 0.0250768 | O18: =H18/G18-1 -> 0.021557708 | P18: =I18/H18-1 -> 0.024890434 | R18: 166.9601 | S18: 167.78 | T18: 170.54713 | U18: 174.81975 | V18: 178.91427 | W18: 182.7711 | X18: 187.58045 | Z18: =S18/R18-1 -> 0.0049107479 | AA18: =T18/S18-1 -> 0.016492642 | AB18: =U18/T18-1 -> 0.025052435 | AC18: =V18/U18-1 -> 0.023421333 | AD18: =W18/V18-1 -> 0.021556889 | AE18: =X18/W18-1 -> 0.026313494 | AG18: =C18-R18 -> 0 | AH18: =D18-S18 -> 0 | AI18: =E18-T18 -> 0.7360526 | AJ18: =F18-U18 -> 0.29065812 | AK18: =G18-V18 -> 0.58735506 | AL18: =H18-W18 -> 0.60016369 | AM18: =I18-X18 -> 0.35500784 | AO18: =C18/R18-1 -> 0 | AP18: =D18/S18-1 -> 0 | AQ18: =E18/T18-1 -> 0.0043158309 | AR18: =F18/U18-1 -> 0.001662616 | AS18: =G18/V18-1 -> 0.0032828856 | AT18: =H18/W18-1 -> 0.0032836903 | AU18: =I18/X18-1 -> 0.0018925631
B19: Paid accom. | C19: =tbl_model!R20 -> 111.19543 | D19: =tbl_model!S20 -> 111.5737 | E19: =tbl_model!T20 -> 114.0746 | F19: =tbl_model!U20 -> 116.79865 | G19: =tbl_model!V20 -> 119.54808 | H19: =tbl_model!W20 -> 122.30863 | I19: =tbl_model!X20 -> 125.35295 | K19: =D19/C19-1 -> 0.0034018729 | L19: =E19/D19-1 -> 0.02241481 | M19: =F19/E19-1 -> 0.023879489 | N19: =G19/F19-1 -> 0.023539953 | O19: =H19/G19-1 -> 0.023091579 | P19: =I19/H19-1 -> 0.024890434 | R19: 111.19543 | S19: 111.5737 | T19: 113.58439 | U19: 116.60478 | V19: 119.1569 | W19: 121.90832 | X19: 125.11616 | Z19: =S19/R19-1 -> 0.0034018729 | AA19: =T19/S19-1 -> 0.018021203 | AB19: =U19/T19-1 -> 0.026591553 | AC19: =V19/U19-1 -> 0.021886969 | AD19: =W19/V19-1 -> 0.023090758 | AE19: =X19/W19-1 -> 0.026313494 | AG19: =C19-R19 -> 0 | AH19: =D19-S19 -> 0 | AI19: =E19-T19 -> 0.49021103 | AJ19: =F19-U19 -> 0.19386896 | AK19: =G19-V19 -> 0.39117847 | AL19: =H19-W19 -> 0.40030918 | AM19: =I19-X19 -> 0.23679023 | AO19: =C19/R19-1 -> 0 | AP19: =D19/S19-1 -> 0 | AQ19: =E19/T19-1 -> 0.0043158309 | AR19: =F19/U19-1 -> 0.001662616 | AS19: =G19/V19-1 -> 0.0032828856 | AT19: =H19/W19-1 -> 0.0032836903 | AU19: =I19/X19-1 -> 0.0018925631
B20: Unpaid accom. | C20: =tbl_model!R21 -> 55.764673 | D20: =tbl_model!S21 -> 56.206299 | E20: =tbl_model!T21 -> 57.208584 | F20: =tbl_model!U21 -> 58.311767 | G20: =tbl_model!V21 -> 59.953542 | H20: =tbl_model!W21 -> 61.062631 | I20: =tbl_model!X21 -> 62.582507 | K20: =D20/C20-1 -> 0.0079194627 | L20: =E20/D20-1 -> 0.017832251 | M20: =F20/E20-1 -> 0.019283526 | N20: =G20/F20-1 -> 0.028155108 | O20: =H20/G20-1 -> 0.018499152 | P20: =I20/H20-1 -> 0.024890434 | R20: 55.764673 | S20: 56.206299 | T20: 56.962743 | U20: 58.214978 | V20: 59.757365 | W20: 60.862777 | X20: 62.464289 | Z20: =S20/R20-1 -> 0.0079194627 | AA20: =T20/S20-1 -> 0.013458336 | AB20: =U20/T20-1 -> 0.021983416 | AC20: =V20/U20-1 -> 0.026494671 | AD20: =W20/V20-1 -> 0.018498335 | AE20: =X20/W20-1 -> 0.026313494 | AG20: =C20-R20 -> 0 | AH20: =D20-S20 -> 0 | AI20: =E20-T20 -> 0.24584157 | AJ20: =F20-U20 -> 0.096789153 | AK20: =G20-V20 -> 0.19617659 | AL20: =H20-W20 -> 0.19985451 | AM20: =I20-X20 -> 0.11821761 | AO20: =C20/R20-1 -> 0 | AP20: =D20/S20-1 -> 0 | AQ20: =E20/T20-1 -> 0.0043158309 | AR20: =F20/U20-1 -> 0.001662616 | AS20: =G20/V20-1 -> 0.0032828856 | AT20: =H20/W20-1 -> 0.0032836903 | AU20: =I20/X20-1 -> 0.0018925631
B22: Gateway | C22: =tbl_model!R23 -> 114.35103 | D22: =tbl_model!S23 -> 115.03944 | E22: =tbl_model!T23 -> 117.46189 | F22: =tbl_model!U23 -> 119.83155 | G22: =tbl_model!V23 -> 122.83255 | H22: =tbl_model!W23 -> 125.67012 | I22: =tbl_model!X23 -> 128.92703 | K22: =D22/C22-1 -> 0.0060200843 | L22: =E22/D22-1 -> 0.021057575 | M22: =F22/E22-1 -> 0.020173847 | N22: =G22/F22-1 -> 0.025043477 | O22: =H22/G22-1 -> 0.023101168 | P22: =I22/H22-1 -> 0.025916351 | R22: 114.35103 | S22: 115.03944 | T22: 116.77449 | U22: 119.36829 | V22: 122.12142 | W22: 124.93696 | X22: 128.35284 | Z22: =S22/R22-1 -> 0.0060200843 | AA22: =T22/S22-1 -> 0.015082284 | AB22: =U22/T22-1 -> 0.022211968 | AC22: =V22/U22-1 -> 0.023064195 | AD22: =W22/V22-1 -> 0.023055275 | AE22: =X22/W22-1 -> 0.027340835 | AG22: =C22-R22 -> 0 | AH22: =D22-S22 -> 0 | AI22: =E22-T22 -> 0.68739414 | AJ22: =F22-U22 -> 0.46326095 | AK22: =G22-V22 -> 0.71112608 | AL22: =H22-W22 -> 0.73315837 | AM22: =I22-X22 -> 0.57418844 | AO22: =C22/R22-1 -> 0 | AP22: =D22/S22-1 -> 0 | AQ22: =E22/T22-1 -> 0.0058865092 | AR22: =F22/U22-1 -> 0.0038809383 | AS22: =G22/V22-1 -> 0.0058231069 | AT22: =H22/W22-1 -> 0.0058682263 | AU22: =I22/X22-1 -> 0.0044735155
B23: Rural/Other | C23: =tbl_model!R24 -> 138.63798 | D23: =tbl_model!S24 -> 139.95693 | E23: =tbl_model!T24 -> 142.08009 | F23: =tbl_model!U24 -> 145.37715 | G23: =tbl_model!V24 -> 148.75514 | H23: =tbl_model!W24 -> 152.0501 | I23: =tbl_model!X24 -> 155.99068 | K23: =D23/C23-1 -> 0.0095136377 | L23: =E23/D23-1 -> 0.015170082 | M23: =F23/E23-1 -> 0.023205624 | N23: =G23/F23-1 -> 0.023236107 | O23: =H23/G23-1 -> 0.02215018 | P23: =I23/H23-1 -> 0.025916351 | R23: 138.63798 | S23: 139.95693 | T23: 141.91007 | U23: 145.66444 | V23: 148.84776 | W23: 152.15055 | X23: 156.31048 | Z23: =S23/R23-1 -> 0.0095136377 | AA23: =T23/S23-1 -> 0.013955274 | AB23: =U23/T23-1 -> 0.026455984 | AC23: =V23/U23-1 -> 0.02185377 | AD23: =W23/V23-1 -> 0.022189095 | AE23: =X23/W23-1 -> 0.027340835 | AG23: =C23-R23 -> 0 | AH23: =D23-S23 -> 0 | AI23: =E23-T23 -> 0.17002077 | AJ23: =F23-U23 -> -0.28729264 | AK23: =G23-V23 -> -0.092610881 | AL23: =H23-W23 -> -0.10045468 | AM23: =I23-X23 -> -0.31979415 | AO23: =C23/R23-1 -> 0 | AP23: =D23/S23-1 -> 0 | AQ23: =E23/T23-1 -> 0.0011980882 | AR23: =F23/U23-1 -> -0.0019722909 | AS23: =G23/V23-1 -> -0.00062218527 | AT23: =H23/W23-1 -> -0.00066023211 | AU23: =I23/X23-1 -> -0.0020458907
B25: Fly | C25: =tbl_model!R26 -> 49.587149 | D25: =tbl_model!S26 -> 50.130543 | E25: =tbl_model!T26 -> 50.692522 | F25: =tbl_model!U26 -> 51.851117 | G25: =tbl_model!V26 -> 53.257574 | H25: =tbl_model!W26 -> 54.514605 | I25: =tbl_model!X26 -> 55.983352 | K25: =D25/C25-1 -> 0.010958355 | L25: =E25/D25-1 -> 0.011210304 | M25: =F25/E25-1 -> 0.022855354 | N25: =G25/F25-1 -> 0.027124905 | O25: =H25/G25-1 -> 0.023602869 | P25: =I25/H25-1 -> 0.026942267 | R25: 49.587149 | S25: 50.130543 | T25: 50.906473 | U25: 52.207882 | V25: 53.537414 | W25: 54.801007 | X25: 56.355611 | Z25: =S25/R25-1 -> 0.010958355 | AA25: =T25/S25-1 -> 0.015478179 | AB25: =U25/T25-1 -> 0.025564705 | AC25: =V25/U25-1 -> 0.025466131 | AD25: =W25/V25-1 -> 0.023602048 | AE25: =X25/W25-1 -> 0.028368176 | AG25: =C25-R25 -> 0 | AH25: =D25-S25 -> 0 | AI25: =E25-T25 -> -0.21395087 | AJ25: =F25-U25 -> -0.35676427 | AK25: =G25-V25 -> -0.27984041 | AL25: =H25-W25 -> -0.28640149 | AM25: =I25-X25 -> -0.37225902 | AO25: =C25/R25-1 -> 0 | AP25: =D25/S25-1 -> 0 | AQ25: =E25/T25-1 -> -0.0042028225 | AR25: =F25/U25-1 -> -0.0068335328 | AS25: =G25/V25-1 -> -0.0052270064 | AT25: =H25/W25-1 -> -0.0052262085 | AU25: =I25/X25-1 -> -0.0066055361
B26: Drive | C26: =tbl_model!R27 -> 203.40186 | D26: =tbl_model!S27 -> 204.86582 | E26: =tbl_model!T27 -> 208.84946 | F26: =tbl_model!U27 -> 213.35758 | G26: =tbl_model!V27 -> 218.33012 | H26: =tbl_model!W27 -> 223.20561 | I26: =tbl_model!X27 -> 228.93436 | K26: =D26/C26-1 -> 0.0071973813 | L26: =E26/D26-1 -> 0.019445074 | M26: =F26/E26-1 -> 0.021585499 | N26: =G26/F26-1 -> 0.023306137 | O26: =H26/G26-1 -> 0.022330849 | P26: =I26/H26-1 -> 0.025665786 | R26: 203.40186 | S26: 204.86582 | T26: 207.77809 | U26: 212.82484 | V26: 217.43176 | W26: 222.28651 | X26: 228.30771 | Z26: =S26/R26-1 -> 0.0071973813 | AA26: =T26/S26-1 -> 0.014215476 | AB26: =U26/T26-1 -> 0.024289148 | AC26: =V26/U26-1 -> 0.021646523 | AD26: =W26/V26-1 -> 0.022327682 | AE26: =X26/W26-1 -> 0.027087561 | AG26: =C26-R26 -> 0 | AH26: =D26-S26 -> 0 | AI26: =E26-T26 -> 1.0713658 | AJ26: =F26-U26 -> 0.53273258 | AK26: =G26-V26 -> 0.8983556 | AL26: =H26-W26 -> 0.91910518 | AM26: =I26-X26 -> 0.62665331 | AO26: =C26/R26-1 -> 0 | AP26: =D26/S26-1 -> 0 | AQ26: =E26/T26-1 -> 0.0051562981 | AR26: =F26/U26-1 -> 0.0025031503 | AS26: =G26/V26-1 -> 0.0041316669 | AT26: =H26/W26-1 -> 0.0041347772 | AU26: =I26/X26-1 -> 0.0027447751
B28: International
B29: Total | C29: =tbl_model!R30 -> 16.516406 | D29: =tbl_model!S30 -> 16.407089 | E29: =tbl_model!T30 -> 16.795061 | F29: =tbl_model!U30 -> 17.292424 | G29: =tbl_model!V30 -> 17.964969 | H29: =tbl_model!W30 -> 18.763757 | I29: =tbl_model!X30 -> 19.548257 | K29: =D29/C29-1 -> -0.0066187189 | L29: =E29/D29-1 -> 0.023646594 | M29: =F29/E29-1 -> 0.029613695 | N29: =G29/F29-1 -> 0.038892445 | O29: =H29/G29-1 -> 0.044463655 | P29: =I29/H29-1 -> 0.041809323 | R29: 16.516406 | S29: 16.407089 | T29: 16.804192 | U29: 17.456358 | V29: 18.186821 | W29: 18.917028 | X29: 19.651401 | Z29: =S29/R29-1 -> -0.0066187189 | AA29: =T29/S29-1 -> 0.024203133 | AB29: =U29/T29-1 -> 0.038809711 | AC29: =V29/U29-1 -> 0.041845139 | AD29: =W29/V29-1 -> 0.040150311 | AE29: =X29/W29-1 -> 0.038820744 | AG29: =C29-R29 -> 0 | AH29: =D29-S29 -> 0 | AI29: =E29-T29 -> -0.0091311787 | AJ29: =F29-U29 -> -0.16393321 | AK29: =G29-V29 -> -0.22185225 | AL29: =H29-W29 -> -0.1532706 | AM29: =I29-X29 -> -0.1031437 | AO29: =C29/R29-1 -> 0 | AP29: =D29/S29-1 -> 0 | AQ29: =E29/T29-1 -> -0.00054338696 | AR29: =F29/U29-1 -> -0.0093910319 | AS29: =G29/V29-1 -> -0.012198517 | AT29: =H29/W29-1 -> -0.0081022556 | AU29: =I29/X29-1 -> -0.0052486689
B30: Overseas | C30: =tbl_model!R31 -> 6.964 | D30: =tbl_model!S31 -> 6.616 | E30: =tbl_model!T31 -> 6.3678526 | F30: =tbl_model!U31 -> 6.5856762 | G30: =tbl_model!V31 -> 6.9358247 | H30: =tbl_model!W31 -> 7.3967461 | I30: =tbl_model!X31 -> 7.865921 | K30: =D30/C30-1 -> -0.049971281 | L30: =E30/D30-1 -> -0.037507157 | M30: =F30/E30-1 -> 0.034206756 | N30: =G30/F30-1 -> 0.05316818 | O30: =H30/G30-1 -> 0.066455178 | P30: =I30/H30-1 -> 0.063429901 | R30: 6.964 | S30: 6.616 | T30: 6.7381292 | U30: 7.1115001 | V30: 7.5267902 | W30: 7.92488 | X30: 8.3898295 | Z30: =S30/R30-1 -> -0.049971281 | AA30: =T30/S30-1 -> 0.018459672 | AB30: =U30/T30-1 -> 0.055411652 | AC30: =V30/U30-1 -> 0.058396982 | AD30: =W30/V30-1 -> 0.052889717 | AE30: =X30/W30-1 -> 0.058669594 | AG30: =C30-R30 -> 0 | AH30: =D30-S30 -> 0 | AI30: =E30-T30 -> -0.37027654 | AJ30: =F30-U30 -> -0.52582383 | AK30: =G30-V30 -> -0.59096555 | AL30: =H30-W30 -> -0.52813389 | AM30: =I30-X30 -> -0.5239085 | AO30: =C30/R30-1 -> 0 | AP30: =D30/S30-1 -> 0 | AQ30: =E30/T30-1 -> -0.054952426 | AR30: =F30/U30-1 -> -0.073939932 | AS30: =G30/V30-1 -> -0.078514949 | AT30: =H30/W30-1 -> -0.066642509 | AU30: =I30/X30-1 -> -0.062445668
B31: Mexico | C31: =tbl_model!R32 -> 7.8261018 | D31: =tbl_model!S32 -> 8.4112547 | E31: =tbl_model!T32 -> 9.1373261 | F31: =tbl_model!U32 -> 9.3928568 | G31: =tbl_model!V32 -> 9.6637419 | H31: =tbl_model!W32 -> 9.9081521 | I31: =tbl_model!X32 -> 10.137294 | K31: =D31/C31-1 -> 0.074769393 | L31: =E31/D31-1 -> 0.086321413 | M31: =F31/E31-1 -> 0.027965593 | N31: =G31/F31-1 -> 0.028839479 | O31: =H31/G31-1 -> 0.025291465 | P31: =I31/H31-1 -> 0.023126614 | R31: 7.8261018 | S31: 8.4112547 | T31: 8.6507701 | U31: 8.8494538 | V31: 9.0776177 | W31: 9.3344299 | X31: 9.5317997 | Z31: =S31/R31-1 -> 0.074769393 | AA31: =T31/S31-1 -> 0.028475583 | AB31: =U31/T31-1 -> 0.022967171 | AC31: =V31/U31-1 -> 0.025782826 | AD31: =W31/V31-1 -> 0.028290701 | AE31: =X31/W31-1 -> 0.021144284 | AG31: =C31-R31 -> 0 | AH31: =D31-S31 -> 0 | AI31: =E31-T31 -> 0.48655601 | AJ31: =F31-U31 -> 0.54340304 | AK31: =G31-V31 -> 0.58612421 | AL31: =H31-W31 -> 0.57372223 | AM31: =I31-X31 -> 0.60549441 | AO31: =C31/R31-1 -> 0 | AP31: =D31/S31-1 -> 0 | AQ31: =E31/T31-1 -> 0.056244242 | AR31: =F31/U31-1 -> 0.061405263 | AS31: =G31/V31-1 -> 0.064568065 | AT31: =H31/W31-1 -> 0.061463018 | AU31: =I31/X31-1 -> 0.063523619
B32: Canada | C32: =tbl_model!R33 -> 1.7263045 | D32: =tbl_model!S33 -> 1.3798342 | E32: =tbl_model!T33 -> 1.2898819 | F32: =tbl_model!U33 -> 1.3138914 | G32: =tbl_model!V33 -> 1.3654025 | H32: =tbl_model!W33 -> 1.4588591 | I32: =tbl_model!X33 -> 1.5450422 | K32: =D32/C32-1 -> -0.20070059 | L32: =E32/D32-1 -> -0.065190635 | M32: =F32/E32-1 -> 0.018613698 | N32: =G32/F32-1 -> 0.039205034 | O32: =H32/G32-1 -> 0.06844614 | P32: =I32/H32-1 -> 0.059075687 | R32: 1.7263045 | S32: 1.3798342 | T32: 1.4152926 | U32: 1.4954038 | V32: 1.5824135 | W32: 1.657718 | X32: 1.7297718 | Z32: =S32/R32-1 -> -0.20070059 | AA32: =T32/S32-1 -> 0.025697564 | AB32: =U32/T32-1 -> 0.056604022 | AC32: =V32/U32-1 -> 0.058184716 | AD32: =W32/V32-1 -> 0.047588425 | AE32: =X32/W32-1 -> 0.043465635 | AG32: =C32-R32 -> 0 | AH32: =D32-S32 -> 0 | AI32: =E32-T32 -> -0.12541064 | AJ32: =F32-U32 -> -0.18151242 | AK32: =G32-V32 -> -0.21701091 | AL32: =H32-W32 -> -0.19885894 | AM32: =I32-X32 -> -0.18472961 | AO32: =C32/R32-1 -> 0 | AP32: =D32/S32-1 -> 0 | AQ32: =E32/T32-1 -> -0.08861111 | AR32: =F32/U32-1 -> -0.12138021 | AS32: =G32/V32-1 -> -0.1371392 | AT32: =H32/W32-1 -> -0.11995945 | AU32: =I32/X32-1 -> -0.10679421
B34: Business | C34: =tbl_model!R35 -> 3.4684453 | D34: =tbl_model!S35 -> 3.4799436 | E34: =tbl_model!T35 -> 3.633477 | F34: =tbl_model!U35 -> 3.7036669 | G34: =tbl_model!V35 -> 3.8092345 | H34: =tbl_model!W35 -> 3.9865642 | I34: =tbl_model!X35 -> 4.14078 | K34: =D34/C34-1 -> 0.0033150939 | L34: =E34/D34-1 -> 0.044119526 | M34: =F34/E34-1 -> 0.019317558 | N34: =G34/F34-1 -> 0.028503521 | O34: =H34/G34-1 -> 0.046552582 | P34: =I34/H34-1 -> 0.038683895 | R34: 3.4684453 | S34: 3.4799436 | T34: 3.5285274 | U34: 3.6288138 | V34: 3.7428554 | W34: 3.9009185 | X34: 4.040198 | Z34: =S34/R34-1 -> 0.0033150939 | AA34: =T34/S34-1 -> 0.013961101 | AB34: =U34/T34-1 -> 0.028421614 | AC34: =V34/U34-1 -> 0.031426688 | AD34: =W34/V34-1 -> 0.042230612 | AE34: =X34/W34-1 -> 0.035704281 | AG34: =C34-R34 -> 0 | AH34: =D34-S34 -> 0 | AI34: =E34-T34 -> 0.10494962 | AJ34: =F34-U34 -> 0.074853073 | AK34: =G34-V34 -> 0.066379021 | AL34: =H34-W34 -> 0.085645648 | AM34: =I34-X34 -> 0.10058199 | AO34: =C34/R34-1 -> 0 | AP34: =D34/S34-1 -> 0 | AQ34: =E34/T34-1 -> 0.029743177 | AR34: =F34/U34-1 -> 0.020627422 | AS34: =G34/V34-1 -> 0.017734861 | AT34: =H34/W34-1 -> 0.021955252 | AU34: =I34/X34-1 -> 0.024895311
B35: Leisure | C35: =tbl_model!R36 -> 13.047961 | D35: =tbl_model!S36 -> 12.927145 | E35: =tbl_model!T36 -> 13.161584 | F35: =tbl_model!U36 -> 13.588758 | G35: =tbl_model!V36 -> 14.155735 | H35: =tbl_model!W36 -> 14.777193 | I35: =tbl_model!X36 -> 15.407477 | K35: =D35/C35-1 -> -0.0092593527 | L35: =E35/D35-1 -> 0.018135351 | M35: =F35/E35-1 -> 0.032456117 | N35: =G35/F35-1 -> 0.041723986 | O35: =H35/G35-1 -> 0.043901536 | P35: =I35/H35-1 -> 0.042652495 | R35: 13.047961 | S35: 12.927145 | T35: 13.275664 | U35: 13.827544 | V35: 14.443966 | W35: 15.016109 | X35: 15.611203 | Z35: =S35/R35-1 -> -0.0092593527 | AA35: =T35/S35-1 -> 0.026960253 | AB35: =U35/T35-1 -> 0.041570755 | AC35: =V35/U35-1 -> 0.044579292 | AD35: =W35/V35-1 -> 0.039611244 | AE35: =X35/W35-1 -> 0.039630345 | AG35: =C35-R35 -> 0 | AH35: =D35-S35 -> 0 | AI35: =E35-T35 -> -0.11408079 | AJ35: =F35-U35 -> -0.23878628 | AK35: =G35-V35 -> -0.28823128 | AL35: =H35-W35 -> -0.23891624 | AM35: =I35-X35 -> -0.20372568 | AO35: =C35/R35-1 -> 0 | AP35: =D35/S35-1 -> 0 | AQ35: =E35/T35-1 -> -0.0085932267 | AR35: =F35/U35-1 -> -0.017268886 | AS35: =G35/V35-1 -> -0.019955134 | AT35: =H35/W35-1 -> -0.015910662 | AU35: =I35/X35-1 -> -0.013049967
B38: Total travel spending ($ billions)
C39: =tbl_model!R40 -> 156.18957 | D39: =tbl_model!S40 -> 158.86462 | E39: =tbl_model!T40 -> 166.25502 | F39: =tbl_model!U40 -> 171.73652 | G39: =tbl_model!V40 -> 178.87832 | H39: =tbl_model!W40 -> 187.2233 | I39: =tbl_model!X40 -> 196.29329 | K39: =D39/C39-1 -> 0.017126961 | L39: =E39/D39-1 -> 0.04652014 | M39: =F39/E39-1 -> 0.032970426 | N39: =G39/F39-1 -> 0.041585792 | O39: =H39/G39-1 -> 0.046651725 | P39: =I39/H39-1 -> 0.048444737 | R39: 156.18957 | S39: 158.86462 | T39: 166.51449 | U39: 172.02342 | V39: 179.24903 | W39: 187.36831 | X39: 196.08746 | Z39: =S39/R39-1 -> 0.017126961 | AA39: =T39/S39-1 -> 0.048153374 | AB39: =U39/T39-1 -> 0.033083783 | AC39: =V39/U39-1 -> 0.042003675 | AD39: =W39/V39-1 -> 0.045296057 | AE39: =X39/W39-1 -> 0.046534822 | AG39: =C39-R39 -> 0 | AH39: =D39-S39 -> 0 | AI39: =E39-T39 -> -0.25946321 | AJ39: =F39-U39 -> -0.28689343 | AK39: =G39-V39 -> -0.37070961 | AL39: =H39-W39 -> -0.14500172 | AM39: =I39-X39 -> 0.20583116 | AO39: =C39/R39-1 -> 0 | AP39: =D39/S39-1 -> 0 | AQ39: =E39/T39-1 -> -0.001558202 | AR39: =F39/U39-1 -> -0.001667758 | AS39: =G39/V39-1 -> -0.0020681262 | AT39: =H39/W39-1 -> -0.00077388605 | AU39: =I39/X39-1 -> 0.0010496906
B40: Domestic | C40: =tbl_model!R41 -> 130.15426 | D40: =tbl_model!S41 -> 133.4499 | E40: =tbl_model!T41 -> 140.24956 | F40: =tbl_model!U41 -> 144.45231 | G40: =tbl_model!V41 -> 150.02783 | H40: =tbl_model!W41 -> 156.39702 | I40: =tbl_model!X41 -> 163.46185 | K40: =D40/C40-1 -> 0.025321087 | L40: =E40/D40-1 -> 0.050952864 | M40: =F40/E40-1 -> 0.029966273 | N40: =G40/F40-1 -> 0.038597606 | O40: =H40/G40-1 -> 0.042453386 | P40: =I40/H40-1 -> 0.045172435 | R40: 130.15426 | S40: 133.4499 | T40: 139.88548 | U40: 143.62312 | V40: 148.94485 | W40: 155.21196 | X40: 161.97158 | Z40: =S40/R40-1 -> 0.025321087 | AA40: =T40/S40-1 -> 0.048224644 | AB40: =U40/T40-1 -> 0.02671934 | AC40: =V40/U40-1 -> 0.037053426 | AD40: =W40/V40-1 -> 0.042076667 | AE40: =X40/W40-1 -> 0.043550951 | AG40: =C40-R40 -> 0 | AH40: =D40-S40 -> 0 | AI40: =E40-T40 -> 0.36408063 | AJ40: =F40-U40 -> 0.82918964 | AK40: =G40-V40 -> 1.0829742 | AL40: =H40-W40 -> 1.1850606 | AM40: =I40-X40 -> 1.4902665 | AO40: =C40/R40-1 -> 0 | AP40: =D40/S40-1 -> 0 | AQ40: =E40/T40-1 -> 0.002602705 | AR40: =F40/U40-1 -> 0.0057733715 | AS40: =G40/V40-1 -> 0.0072709746 | AT40: =H40/W40-1 -> 0.0076351115 | AU40: =I40/X40-1 -> 0.0092007896
B41: Business | C41: =tbl_model!R42 -> 28.351607 | D41: =tbl_model!S42 -> 28.706106 | E41: =tbl_model!T42 -> 30.501767 | F41: =tbl_model!U42 -> 31.880928 | G41: =tbl_model!V42 -> 32.946302 | H41: =tbl_model!W42 -> 34.613149 | I41: =tbl_model!X42 -> 36.255019 | K41: =D41/C41-1 -> 0.012503662 | L41: =E41/D41-1 -> 0.062553281 | M41: =F41/E41-1 -> 0.045215772 | N41: =G41/F41-1 -> 0.033417273 | O41: =H41/G41-1 -> 0.05059284 | P41: =I41/H41-1 -> 0.047434883 | R41: 28.351607 | S41: 28.706106 | T41: 30.083837 | U41: 31.533489 | V41: 32.532555 | W41: 34.180618 | X41: 35.85394 | Z41: =S41/R41-1 -> 0.012503662 | AA41: =T41/S41-1 -> 0.047994354 | AB41: =U41/T41-1 -> 0.048187055 | AC41: =V41/U41-1 -> 0.031682713 | AD41: =W41/V41-1 -> 0.05065889 | AE41: =X41/W41-1 -> 0.04895528 | AG41: =C41-R41 -> 0 | AH41: =D41-S41 -> 0 | AI41: =E41-T41 -> 0.4179301 | AJ41: =F41-U41 -> 0.34743952 | AK41: =G41-V41 -> 0.41374672 | AL41: =H41-W41 -> 0.43253054 | AM41: =I41-X41 -> 0.40107947 | AO41: =C41/R41-1 -> 0 | AP41: =D41/S41-1 -> 0 | AQ41: =E41/T41-1 -> 0.013892181 | AR41: =F41/U41-1 -> 0.011018112 | AS41: =G41/V41-1 -> 0.012717929 | AT41: =H41/W41-1 -> 0.012654263 | AU41: =I41/X41-1 -> 0.011186482
B42: Group | C42: =tbl_model!R43 -> 4.8713201 | D42: =tbl_model!S43 -> 5.0605907 | E42: =tbl_model!T43 -> 5.3609944 | F42: =tbl_model!U43 -> 5.5642281 | G42: =tbl_model!V43 -> 5.7501637 | H42: =tbl_model!W43 -> 6.053169 | I42: =tbl_model!X43 -> 6.340294 | K42: =D42/C42-1 -> 0.038854069 | L42: =E42/D42-1 -> 0.05936137 | M42: =F42/E42-1 -> 0.037909713 | N42: =G42/F42-1 -> 0.033416239 | O42: =H42/G42-1 -> 0.052695076 | P42: =I42/H42-1 -> 0.047433835 | R42: 4.8713201 | S42: 5.0605907 | T42: 5.3618617 | U42: 5.5809486 | V42: 5.7577625 | W42: 6.0615493 | X42: 6.3582877 | Z42: =S42/R42-1 -> 0.038854069 | AA42: =T42/S42-1 -> 0.059532771 | AB42: =U42/T42-1 -> 0.040860228 | AC42: =V42/U42-1 -> 0.031681681 | AD42: =W42/V42-1 -> 0.052761259 | AE42: =X42/W42-1 -> 0.048954231 | AG42: =C42-R42 -> 0 | AH42: =D42-S42 -> 0 | AI42: =E42-T42 -> -0.00086739043 | AJ42: =F42-U42 -> -0.016720523 | AK42: =G42-V42 -> -0.007598781 | AL42: =H42-W42 -> -0.0083802643 | AM42: =I42-X42 -> -0.017993725 | AO42: =C42/R42-1 -> 0 | AP42: =D42/S42-1 -> 0 | AQ42: =E42/T42-1 -> -0.00016177038 | AR42: =F42/U42-1 -> -0.0029960001 | AS42: =G42/V42-1 -> -0.0013197455 | AT42: =H42/W42-1 -> -0.0013825284 | AU42: =I42/X42-1 -> -0.0028299639
B43: Leisure | C43: =tbl_model!R44 -> 101.80265 | D43: =tbl_model!S44 -> 104.7438 | E43: =tbl_model!T44 -> 109.74779 | F43: =tbl_model!U44 -> 112.57139 | G43: =tbl_model!V44 -> 117.08153 | H43: =tbl_model!W44 -> 121.78387 | I43: =tbl_model!X44 -> 127.20683 | K43: =D43/C43-1 -> 0.028890686 | L43: =E43/D43-1 -> 0.047773651 | M43: =F43/E43-1 -> 0.025728041 | N43: =G43/F43-1 -> 0.040064709 | O43: =H43/G43-1 -> 0.040162975 | P43: =I43/H43-1 -> 0.044529407 | R43: 101.80265 | S43: 104.7438 | T43: 109.80164 | U43: 112.08964 | V43: 116.4123 | W43: 121.03134 | X43: 126.11764 | Z43: =S43/R43-1 -> 0.028890686 | AA43: =T43/S43-1 -> 0.048287757 | AB43: =U43/T43-1 -> 0.02083754 | AC43: =V43/U43-1 -> 0.038564336 | AD43: =W43/V43-1 -> 0.039678281 | AE43: =X43/W43-1 -> 0.042024707 | AG43: =C43-R43 -> 0 | AH43: =D43-S43 -> 0 | AI43: =E43-T43 -> -0.053849474 | AJ43: =F43-U43 -> 0.48175012 | AK43: =G43-V43 -> 0.66922753 | AL43: =H43-W43 -> 0.75253004 | AM43: =I43-X43 -> 1.089187 | AO43: =C43/R43-1 -> 0 | AP43: =D43/S43-1 -> 0 | AQ43: =E43/T43-1 -> -0.00049042505 | AR43: =F43/U43-1 -> 0.0042979007 | AS43: =G43/V43-1 -> 0.00574877 | AT43: =H43/W43-1 -> 0.0062176462 | AU43: =I43/X43-1 -> 0.0086362777
B44: International | C44: =tbl_model!R45 -> 26.035312 | D44: =tbl_model!S45 -> 25.414717 | E44: =tbl_model!T45 -> 26.005467 | F44: =tbl_model!U45 -> 27.284209 | G44: =tbl_model!V45 -> 28.850495 | H44: =tbl_model!W45 -> 30.826288 | I44: =tbl_model!X45 -> 32.831438 | K44: =D44/C44-1 -> -0.023836646 | L44: =E44/D44-1 -> 0.02324439 | M44: =F44/E44-1 -> 0.049172061 | N44: =G44/F44-1 -> 0.057406317 | O44: =H44/G44-1 -> 0.068483848 | P44: =I44/H44-1 -> 0.065046742 | R44: 26.035312 | S44: 25.414717 | T44: 26.629011 | U44: 28.400292 | V44: 30.304179 | W44: 32.156351 | X44: 34.115873 | Z44: =S44/R44-1 -> -0.023836646 | AA44: =T44/S44-1 -> 0.047779144 | AB44: =U44/T44-1 -> 0.06651699 | AC44: =V44/U44-1 -> 0.067037576 | AD44: =W44/V44-1 -> 0.061119339 | AE44: =X44/W44-1 -> 0.060937345 | AG44: =C44-R44 -> 0 | AH44: =D44-S44 -> 0 | AI44: =E44-T44 -> -0.62354384 | AJ44: =F44-U44 -> -1.1160831 | AK44: =G44-V44 -> -1.4536839 | AL44: =H44-W44 -> -1.3300623 | AM44: =I44-X44 -> -1.2844353 | AO44: =C44/R44-1 -> 0 | AP44: =D44/S44-1 -> 0 | AQ44: =E44/T44-1 -> -0.023415959 | AR44: =F44/U44-1 -> -0.039298295 | AS44: =G44/V44-1 -> -0.047969749 | AT44: =H44/W44-1 -> -0.041362352 | AU44: =I44/X44-1 -> -0.037649199
B45: Business | C45: =tbl_model!R46 -> 5.8787734 | D45: =tbl_model!S46 -> 5.7909467 | E45: =tbl_model!T46 -> 6.0336626 | F45: =tbl_model!U46 -> 6.4869087 | G45: =tbl_model!V46 -> 6.7993604 | H45: =tbl_model!W46 -> 7.2776872 | I45: =tbl_model!X46 -> 7.7307786 | K45: =D45/C45-1 -> -0.014939639 | L45: =E45/D45-1 -> 0.041912994 | M45: =F45/E45-1 -> 0.075119568 | N45: =G45/F45-1 -> 0.048166503 | O45: =H45/G45-1 -> 0.070348794 | P45: =I45/H45-1 -> 0.062257614 | R45: 5.8787734 | S45: 5.7909467 | T45: 6.0122826 | U45: 6.5787242 | V45: 6.9586397 | W45: 7.3967857 | X45: 7.827054 | Z45: =S45/R45-1 -> -0.014939639 | AA45: =T45/S45-1 -> 0.03822103 | AB45: =U45/T45-1 -> 0.094214069 | AC45: =V45/U45-1 -> 0.057749118 | AD45: =W45/V45-1 -> 0.062964313 | AE45: =X45/W45-1 -> 0.058169636 | AG45: =C45-R45 -> 0 | AH45: =D45-S45 -> 0 | AI45: =E45-T45 -> 0.021379965 | AJ45: =F45-U45 -> -0.091815516 | AK45: =G45-V45 -> -0.15927933 | AL45: =H45-W45 -> -0.1190985 | AM45: =I45-X45 -> -0.096275389 | AO45: =C45/R45-1 -> 0 | AP45: =D45/S45-1 -> 0 | AQ45: =E45/T45-1 -> 0.0035560479 | AR45: =F45/U45-1 -> -0.013956432 | AS45: =G45/V45-1 -> -0.022889435 | AT45: =H45/W45-1 -> -0.016101386 | AU45: =I45/X45-1 -> -0.012300335
B46: Leisure | C46: =tbl_model!R47 -> 20.156538 | D46: =tbl_model!S47 -> 19.623771 | E46: =tbl_model!T47 -> 19.971804 | F46: =tbl_model!U47 -> 20.797301 | G46: =tbl_model!V47 -> 22.051135 | H46: =tbl_model!W47 -> 23.548601 | I46: =tbl_model!X47 -> 25.100659 | K46: =D46/C46-1 -> -0.026431511 | L46: =E46/D46-1 -> 0.017735312 | M46: =F46/E46-1 -> 0.041333085 | N46: =G46/F46-1 -> 0.060288318 | O46: =H46/G46-1 -> 0.067908801 | P46: =I46/H46-1 -> 0.065908721 | R46: 20.156538 | S46: 19.623771 | T46: 20.616728 | U46: 21.821568 | V46: 23.345539 | W46: 24.759565 | X46: 26.288819 | Z46: =S46/R46-1 -> -0.026431511 | AA46: =T46/S46-1 -> 0.05059973 | AB46: =U46/T46-1 -> 0.058439925 | AC46: =V46/U46-1 -> 0.069837842 | AD46: =W46/V46-1 -> 0.060569404 | AE46: =X46/W46-1 -> 0.061764183 | AG46: =C46-R46 -> 0 | AH46: =D46-S46 -> 0 | AI46: =E46-T46 -> -0.6449238 | AJ46: =F46-U46 -> -1.0242676 | AK46: =G46-V46 -> -1.2944045 | AL46: =H46-W46 -> -1.2109638 | AM46: =I46-X46 -> -1.1881599 | AO46: =C46/R46-1 -> 0 | AP46: =D46/S46-1 -> 0 | AQ46: =E46/T46-1 -> -0.031281579 | AR46: =F46/U46-1 -> -0.046938311 | AS46: =G46/V46-1 -> -0.055445475 | AT46: =H46/W46-1 -> -0.048908929 | AU46: =I46/X46-1 -> -0.045196397
B48: Source: Tourism Economics; STR; Omnitrak (domestic); OAG (air traffic); NTTO (international); Dean Runyan (spending); VisaVue; BTS
B52: Annual domestic leisure trips to California (millions)
C54: 2024 | D54: 2025 | E54: 2026 | F54: 2027 | G54: 2028 | H54: 2029 | I54: 2030 | K54: 2025 | L54: 2026 | M54: 2027 | N54: 2028 | O54: 2029 | P54: 2030 | R54: 2024 | S54: 2025 | T54: 2026 | U54: 2027 | V54: 2028 | W54: 2029 | X54: 2030 | Z54: 2025 | AA54: 2026 | AB54: 2027 | AC54: 2028 | AD54: 2029 | AE54: 2030 | AG54: 2024 | AH54: 2025 | AI54: 2026 | AJ54: 2027 | AK54: 2028 | AL54: 2029 | AM54: 2030 | AO54: 2024 | AP54: 2025 | AQ54: 2026 | AR54: 2027 | AS54: 2028 | AT54: 2029 | AU54: 2030
B56: Total | C56: =tbl_model!R57 -> 212.25778 | D56: =tbl_model!S57 -> 214.15589 | E56: =tbl_model!T57 -> 217.7555 | F56: =tbl_model!U57 -> 221.84234 | G56: =tbl_model!V57 -> 227.40544 | H56: =tbl_model!W57 -> 232.30778 | I56: =tbl_model!X57 -> 238.09002 | K56: =D56/C56-1 -> 0.0089424861 | L56: =E56/D56-1 -> 0.016808348 | M56: =F56/E56-1 -> 0.01876802 | N56: =G56/F56-1 -> 0.0250768 | O56: =H56/G56-1 -> 0.021557708 | P56: =I56/H56-1 -> 0.024890434 | R56: 212.25778 | S56: 214.15589 | T56: 217.47064 | U56: 222.13898 | V56: 227.34177 | W56: 232.24255 | X56: 238.35367 | Z56: =S56/R56-1 -> 0.0089424861 | AA56: =T56/S56-1 -> 0.015478179 | AB56: =U56/T56-1 -> 0.021466544 | AC56: =V56/U56-1 -> 0.023421333 | AD56: =W56/V56-1 -> 0.021556889 | AE56: =X56/W56-1 -> 0.026313494 | AG56: =C56-R56 -> 0 | AH56: =D56-S56 -> 0 | AI56: =E56-T56 -> 0.28486362 | AJ56: =F56-U56 -> -0.29663978 | AK56: =G56-V56 -> 0.063664992 | AL56: =H56-W56 -> 0.065223737 | AM56: =I56-X56 -> -0.26364783 | AO56: =C56/R56-1 -> 0 | AP56: =D56/S56-1 -> 0 | AQ56: =E56/T56-1 -> 0.0013098946 | AR56: =F56/U56-1 -> -0.0013353792 | AS56: =G56/V56-1 -> 0.00028004089 | AT56: =H56/W56-1 -> 0.00028084318 | AU56: =I56/X56-1 -> -0.0011061203
B58: California | C58: =tbl_model!R59 -> 118.3322 | D58: =tbl_model!S59 -> 118.90906 | E58: =tbl_model!T59 -> 120.82582 | F58: =tbl_model!U59 -> 123.1739 | G58: =tbl_model!V59 -> 126.29091 | H58: =tbl_model!W59 -> 128.8474 | I58: =tbl_model!X59 -> 131.86059 | K58: =D58/C58-1 -> 0.0048749568 | L58: =E58/D58-1 -> 0.016119536 | M58: =F58/E58-1 -> 0.019433633 | N58: =G58/F58-1 -> 0.025305732 | O58: =H58/G58-1 -> 0.020242836 | P58: =I58/H58-1 -> 0.023385736 | R58: 118.3322 | S58: 118.90906 | T58: 120.85581 | U58: 123.37509 | V58: 126.38725 | W58: 129.05769 | X58: 132.4986 | Z58: =S58/R58-1 -> 0.0048749568 | AA58: =T58/S58-1 -> 0.016371737 | AB58: =U58/T58-1 -> 0.020845336 | AC58: =V58/U58-1 -> 0.024414636 | AD58: =W58/V58-1 -> 0.021129091 | AE58: =X58/W58-1 -> 0.026661763 | AG58: =C58-R58 -> 0 | AH58: =D58-S58 -> 0 | AI58: =E58-T58 -> -0.029988937 | AJ58: =F58-U58 -> -0.20118418 | AK58: =G58-V58 -> -0.096336217 | AL58: =H58-W58 -> -0.2102977 | AM58: =I58-X58 -> -0.63801219 | AO58: =C58/R58-1 -> 0 | AP58: =D58/S58-1 -> 0 | AQ58: =E58/T58-1 -> -0.00024813815 | AR58: =F58/U58-1 -> -0.001630671 | AS58: =G58/V58-1 -> -0.00076223052 | AT58: =H58/W58-1 -> -0.0016294859 | AU58: =I58/X58-1 -> -0.0048152372
...

Sheet tbl_dwnside
B1: Sept 2026
D4: Baseline Forecast | J4: Downside Scenario | Q4: Baseline Forecast (% change) | W4: Downside Scenario (% change)
D5: Forecast >> | J5: Forecast >> | Q5: Forecast >> | W5: Forecast >>
